Workbook

Sheet Datos
C1: 470 MHz | D1: 862 MHz
A2: Cable coaxial T-100 241
B3: Pérdidas (dB/m) | C3: =0.12 -> 0.12 | D3: =0.15 -> 0.15
A4: Derivador 544602
B5: Pérdidas de paso (dB) | C5: =0.8 -> 0.8 | D5: =C5 -> 0.8
B6: Pérdidas de derivación (dB) | C6: =21 -> 21 | D6: =C6 -> 21
A7: Derivador 544502
B8: Pérdidas de paso (dB) | C8: =3.3 -> 3.3 | D8: =C8 -> 3.3
B9: Pérdidas de derivación (dB) | C9: =17 -> 17 | D9: =C9 -> 17
A10: Derivador 544402
B11: Pérdidas de paso (dB) | C11: =3.5 -> 3.5 | D11: =C11 -> 3.5
B12: Pérdidas de derivación (dB) | C12: =13 -> 13 | D12: =C12 -> 13
A13: Derivador 542503
B14: Pérdidas de paso (dB) | C14: =4 -> 4 | D14: =C14 -> 4
B15: Pérdidas de derivación (dB) | C15: =14 -> 14 | D15: =C15 -> 14
A16: PAU Repartidor 4D 544902
B17: Pérdidas de paso (dB) | C17: =9 -> 9 | D17: =C17 -> 9
A18: PAU Repartidor 5D 5454
B19: Pérdidas de paso (dB) | C19: =13 -> 13 | D19: =C19 -> 13
A20: Toma 5229
B21: Pérdidas de derivación (dB) | C21: =4 -> 4 | D21: =C21 -> 4

Sheet Atenuación tomas
E1: Longitud cable (m) | F1: 470 MHz | G1: 862 MHz
A2: Planta Ático
B3: Vivienda 1
C4: Toma 1, V1, PA
D5: Pérdidas 3 metros de cable coaxial | E5: =3 -> 3 | F5: =Datos!C$3*'Atenuación tomas'!$E5 -> 0.36 | G5: =Datos!D$3*'Atenuación tomas'!$E5 -> 0.45
D6: Pérdidas de derivación derivador Televés 5446 (4D) | F6: =Datos!C$6 -> 21 | G6: =Datos!D$6 -> 21
D7: Pérdidas 1,17 metros de cable coaxial | E7: =1.17 -> 1.17 | F7: =Datos!C$3*'Atenuación tomas'!$E7 -> 0.1404 | G7: =Datos!D$3*'Atenuación tomas'!$E7 -> 0.1755
D8: Pérdidas de inserción o paso PAU Televés 544902 (4D) | F8: =Datos!C$17 -> 9 | G8: =Datos!D$17 -> 9
D9: Pérdidas 5,83 metros de cable coaxial | E9: =5.83 -> 5.83 | F9: =Datos!C$3*'Atenuación tomas'!$E9 -> 0.6996 | G9: =Datos!D$3*'Atenuación tomas'!$E9 -> 0.8745
D10: Pérdidas derivación toma Televés 5229 | F10: =Datos!C$21 -> 4 | G10: =Datos!D$21 -> 4
D11: Atenuación Total | F11: =SUM(F5:F10) -> 35.2 | G11: =SUM(G5:G10) -> 35.5
C12: Toma 2, V1, PA
D13: Pérdidas 3 metros de cable coaxial | E13: =3 -> 3 | F13: =Datos!C$3*'Atenuación tomas'!$E13 -> 0.36 | G13: =Datos!D$3*'Atenuación tomas'!$E13 -> 0.45
D14: Pérdidas de derivación derivador Televés 5446 (4D) | F14: =Datos!C$6 -> 21 | G14: =Datos!D$6 -> 21
D15: Pérdidas 1,17 metros de cable coaxial | E15: =1.17 -> 1.17 | F15: =Datos!C$3*'Atenuación tomas'!$E15 -> 0.1404 | G15: =Datos!D$3*'Atenuación tomas'!$E15 -> 0.1755
D16: Pérdidas de inserción o paso PAU Televés 544902 (4D) | F16: =Datos!C$17 -> 9 | G16: =Datos!D$17 -> 9
D17: Pérdidas 6,19 metros de cable coaxial | E17: =6.19 -> 6.19 | F17: =Datos!C$3*'Atenuación tomas'!$E17 -> 0.7428 | G17: =Datos!D$3*'Atenuación tomas'!$E17 -> 0.9285
D18: Pérdidas derivación toma Televés 5229 | F18: =Datos!C$21 -> 4 | G18: =Datos!D$21 -> 4
D19: Atenuación Total | F19: =SUM(F13:F18) -> 35.2432 | G19: =SUM(G13:G18) -> 35.554
C20: Toma 3, V1, PA
D21: Pérdidas 3 metros de cable coaxial | E21: =3 -> 3 | F21: =Datos!C$3*'Atenuación tomas'!$E21 -> 0.36 | G21: =Datos!D$3*'Atenuación tomas'!$E21 -> 0.45
D22: Pérdidas de derivación derivador Televés 5446 (4D) | F22: =Datos!C$6 -> 21 | G22: =Datos!D$6 -> 21
D23: Pérdidas 1,17 metros de cable coaxial | E23: =1.17 -> 1.17 | F23: =Datos!C$3*'Atenuación tomas'!$E23 -> 0.1404 | G23: =Datos!D$3*'Atenuación tomas'!$E23 -> 0.1755
D24: Pérdidas de inserción o paso PAU Televés 544902 (4D) | F24: =Datos!C$17 -> 9 | G24: =Datos!D$17 -> 9
D25: Pérdidas 7,22 metros de cable coaxial | E25: =7.22 -> 7.22 | F25: =Datos!C$3*'Atenuación tomas'!$E25 -> 0.8664 | G25: =Datos!D$3*'Atenuación tomas'!$E25 -> 1.083
D26: Pérdidas derivación toma Televés 5229 | F26: =Datos!C$21 -> 4 | G26: =Datos!D$21 -> 4
D27: Atenuación Total | F27: =SUM(F21:F26) -> 35.3668 | G27: =SUM(G21:G26) -> 35.7085
C28: Toma 4, V1, PA
D29: Pérdidas 3 metros de cable coaxial | E29: =3 -> 3 | F29: =Datos!C$3*'Atenuación tomas'!$E29 -> 0.36 | G29: =Datos!D$3*'Atenuación tomas'!$E29 -> 0.45
D30: Pérdidas de derivación derivador Televés 5446 (4D) | F30: =Datos!C$6 -> 21 | G30: =Datos!D$6 -> 21
D31: Pérdidas 1,17 metros de cable coaxial | E31: =1.17 -> 1.17 | F31: =Datos!C$3*'Atenuación tomas'!$E31 -> 0.1404 | G31: =Datos!D$3*'Atenuación tomas'!$E31 -> 0.1755
D32: Pérdidas de inserción o paso PAU Televés 544902 (4D) | F32: =Datos!C$17 -> 9 | G32: =Datos!D$17 -> 9
D33: Pérdidas 6,62 metros de cable coaxial | E33: =6.62 -> 6.62 | F33: =Datos!C$3*'Atenuación tomas'!$E33 -> 0.7944 | G33: =Datos!D$3*'Atenuación tomas'!$E33 -> 0.993
D34: Pérdidas derivación toma Televés 5229 | F34: =Datos!C$21 -> 4 | G34: =Datos!D$21 -> 4
D35: Atenuación Total | F35: =SUM(F29:F34) -> 35.2948 | G35: =SUM(G29:G34) -> 35.6185
B36: Vivienda 2
C37: Toma 1, V2, PA
D38: Pérdidas 3 metros de cable coaxial | E38: =3 -> 3 | F38: =Datos!C$3*'Atenuación tomas'!$E38 -> 0.36 | G38: =Datos!D$3*'Atenuación tomas'!$E38 -> 0.45
D39: Pérdidas de derivación derivador Televés 5446 (4D) | F39: =Datos!C$6 -> 21 | G39: =Datos!D$6 -> 21
D40: Pérdidas 4,54 metros de cable coaxial | E40: =4.54 -> 4.54 | F40: =Datos!C$3*'Atenuación tomas'!$E40 -> 0.5448 | G40: =Datos!D$3*'Atenuación tomas'!$E40 -> 0.681
...

Sheet Resumen Atenuación tomas
E1: Longitud cable (m) | F1: 470 MHz | G1: 862 MHz
A2: Planta Ático
B3: Vivienda 1
C4: Toma 1, V1, PA
D5: Pérdidas 3 metros de cable coaxial | E5: =3 -> 3 | F5: =Datos!C$3*'Resumen Atenuación tomas'!$E5 -> 0.36 | G5: =Datos!D$3*'Resumen Atenuación tomas'!$E5 -> 0.45
D6: Pérdidas de derivación derivador Televés 5446 (4D) | F6: =Datos!C$6 -> 21 | G6: =Datos!D$6 -> 21
D7: Pérdidas 1,17 metros de cable coaxial | E7: =1.17 -> 1.17 | F7: =Datos!C$3*'Resumen Atenuación tomas'!$E7 -> 0.1404 | G7: =Datos!D$3*'Resumen Atenuación tomas'!$E7 -> 0.1755
D8: Pérdidas de inserción o paso PAU Televés 544902 (4D) | F8: =Datos!C$17 -> 9 | G8: =Datos!D$17 -> 9
D9: Pérdidas 5,83 metros de cable coaxial | E9: =5.83 -> 5.83 | F9: =Datos!C$3*'Resumen Atenuación tomas'!$E9 -> 0.6996 | G9: =Datos!D$3*'Resumen Atenuación tomas'!$E9 -> 0.8745
D10: Pérdidas derivación toma Televés 5229 | F10: =Datos!C$21 -> 4 | G10: =Datos!D$21 -> 4
D11: Atenuación Total | F11: =SUM(F5:F10) -> 35.2 | G11: =SUM(G5:G10) -> 35.5
C12: Toma 2, V1, PA
D13: Pérdidas 3 metros de cable coaxial | E13: =3 -> 3 | F13: =Datos!C$3*'Resumen Atenuación tomas'!$E13 -> 0.36 | G13: =Datos!D$3*'Resumen Atenuación tomas'!$E13 -> 0.45
D14: Pérdidas de derivación derivador Televés 5446 (4D) | F14: =Datos!C$6 -> 21 | G14: =Datos!D$6 -> 21
D15: Pérdidas 1,17 metros de cable coaxial | E15: =1.17 -> 1.17 | F15: =Datos!C$3*'Resumen Atenuación tomas'!$E15 -> 0.1404 | G15: =Datos!D$3*'Resumen Atenuación tomas'!$E15 -> 0.1755
D16: Pérdidas de inserción o paso PAU Televés 544902 (4D) | F16: =Datos!C$17 -> 9 | G16: =Datos!D$17 -> 9
D17: Pérdidas 6,19 metros de cable coaxial | E17: =6.19 -> 6.19 | F17: =Datos!C$3*'Resumen Atenuación tomas'!$E17 -> 0.7428 | G17: =Datos!D$3*'Resumen Atenuación tomas'!$E17 -> 0.9285
D18: Pérdidas derivación toma Televés 5229 | F18: =Datos!C$21 -> 4 | G18: =Datos!D$21 -> 4
D19: Atenuación Total | F19: =SUM(F13:F18) -> 35.2432 | G19: =SUM(G13:G18) -> 35.554
C20: Toma 3, V1, PA
D21: Pérdidas 3 metros de cable coaxial | E21: =3 -> 3 | F21: =Datos!C$3*'Resumen Atenuación tomas'!$E21 -> 0.36 | G21: =Datos!D$3*'Resumen Atenuación tomas'!$E21 -> 0.45
D22: Pérdidas de derivación derivador Televés 5446 (4D) | F22: =Datos!C$6 -> 21 | G22: =Datos!D$6 -> 21
D23: Pérdidas 1,17 metros de cable coaxial | E23: =1.17 -> 1.17 | F23: =Datos!C$3*'Resumen Atenuación tomas'!$E23 -> 0.1404 | G23: =Datos!D$3*'Resumen Atenuación tomas'!$E23 -> 0.1755
D24: Pérdidas de inserción o paso PAU Televés 544902 (4D) | F24: =Datos!C$17 -> 9 | G24: =Datos!D$17 -> 9
D25: Pérdidas 7,22 metros de cable coaxial | E25: =7.22 -> 7.22 | F25: =Datos!C$3*'Resumen Atenuación tomas'!$E25 -> 0.8664 | G25: =Datos!D$3*'Resumen Atenuación tomas'!$E25 -> 1.083
D26: Pérdidas derivación toma Televés 5229 | F26: =Datos!C$21 -> 4 | G26: =Datos!D$21 -> 4
D27: Atenuación Total | F27: =SUM(F21:F26) -> 35.3668 | G27: =SUM(G21:G26) -> 35.7085
C28: Toma 4, V1, PA
D29: Pérdidas 3 metros de cable coaxial | E29: =3 -> 3 | F29: =Datos!C$3*'Resumen Atenuación tomas'!$E29 -> 0.36 | G29: =Datos!D$3*'Resumen Atenuación tomas'!$E29 -> 0.45
D30: Pérdidas de derivación derivador Televés 5446 (4D) | F30: =Datos!C$6 -> 21 | G30: =Datos!D$6 -> 21
D31: Pérdidas 1,17 metros de cable coaxial | E31: =1.17 -> 1.17 | F31: =Datos!C$3*'Resumen Atenuación tomas'!$E31 -> 0.1404 | G31: =Datos!D$3*'Resumen Atenuación tomas'!$E31 -> 0.1755
D32: Pérdidas de inserción o paso PAU Televés 544902 (4D) | F32: =Datos!C$17 -> 9 | G32: =Datos!D$17 -> 9
D33: Pérdidas 6,62 metros de cable coaxial | E33: =6.62 -> 6.62 | F33: =Datos!C$3*'Resumen Atenuación tomas'!$E33 -> 0.7944 | G33: =Datos!D$3*'Resumen Atenuación tomas'!$E33 -> 0.993
D34: Pérdidas derivación toma Televés 5229 | F34: =Datos!C$21 -> 4 | G34: =Datos!D$21 -> 4
D35: Atenuación Total | F35: =SUM(F29:F34) -> 35.2948 | G35: =SUM(G29:G34) -> 35.6185
B36: Vivienda 2
C37: Toma 1, V2, PA
D38: Pérdidas 3 metros de cable coaxial | E38: =3 -> 3 | F38: =Datos!C$3*'Resumen Atenuación tomas'!$E38 -> 0.36 | G38: =Datos!D$3*'Resumen Atenuación tomas'!$E38 -> 0.45
D39: Pérdidas de derivación derivador Televés 5446 (4D) | F39: =Datos!C$6 -> 21 | G39: =Datos!D$6 -> 21
D40: Pérdidas 4,54 metros de cable coaxial | E40: =4.54 -> 4.54 | F40: =Datos!C$3*'Resumen Atenuación tomas'!$E40 -> 0.5448 | G40: =Datos!D$3*'Resumen Atenuación tomas'!$E40 -> 0.681
...
